Workbook

Sheet Read me
A1: How to use this workbook
A2: Top1Movers Operations Portal, stakeholder mockup. Scenario-based user acceptance test (UAT). Source: docs/testing/UAT-test-plan.md.
A4: The sheets
A5: Summary | B5: Live progress by role, case type and journey, plus defect counts. Read only.
A6: Test Cases | B6: 183 cases, one row each. Filter by Role or Area, then work down the list.
A7: E2E Journeys | B7: 6 multi-person journeys, one row per step. Set a Status on every step.
A8: Defects | B8: Log every failure here (Severity and Status have dropdowns). Put the ID (for example D-001) in the Defect ID column of the failed case.
A9: Test Data | B9: The people, sample shipments, sample quotations and key numbers you test against.
A10: Permission Matrix | B10: What each role may do. Use it to judge Access cases.
A11: Coverage | B11: Which cases test each feature.
A12: Known Limitations | B12: Mockup boundaries and open questions. Not defects.
A14: Filling it in
A15: Yellow cells | B15: These are yours to edit: Status, Tester, Date tested, Defect ID and Notes. Everything else is fixed text or a formula.
A16: Status | B16: Choose from the dropdown: Not run (start), Pass (every part of the expected result is true), Fail (any part differs), Blocked (you could not run it, for example an earlier case left the data in the wrong state).
A17: Type | B17: Happy = the normal path works. Wrong = something goes wrong and the system must cope. Edge = unusual but valid. Access = a role must be able to do, or be blocked from, something.
A18: Severity | B18: Critical = a role sees or does what it must not, or the page breaks. Major = a feature gives a wrong result. Minor = wording, layout or polish.
A19: Data reset | B19: Data lives only in the open page. Refresh the page (F5) to restore the sample data, then sign in again. Cases are written to run in order on one page load unless they say "Refresh first".
A20: "Today" | B20: The mockup clock is fixed at Monday 28 September 2026. All overdue and due-in-N-days statements assume this date.
A21: Run order | B21: Read the full plan sections 1 to 3 (how to open the app, accounts, permission matrix, sample data) before the first case. Then run your own role, then the journeys with a colleague.
A23: Example
A24: A finished row looks like: | B24: DSP-35 | Fail | Maria Santos | 29 Sep 2026 | D-004 | Task completed with no file; expected the message "Attach the completion evidence first."
A26: Sign-off
A27: Role tested | B27: Tester name | Date | Comments
A28: Everyone
A29: Dispatcher
A30: Warehouse Crew
A31: Manager
A32: Admin
A33: Finance
A34: Customer
A35: Cross-cutting
A36: Data check
A37: End-to-end
A39: Approved by | B39: Project sponsor: ______________ Operations lead: ______________ Finance lead: ______________ Date: __________

Sheet Summary
A1: Top1Movers Operations Portal: UAT progress
A2: Counts update by themselves from the Status column on the Test Cases and E2E Journeys sheets. Do not type in this sheet.
A4: Progress by role (point of view)
A5: Role | B5: Cases | C5: Pass | D5: Fail | E5: Blocked | F5: Not run | G5: % run | H5: Pass rate of those run
A6: Everyone | B6: =COUNTIF('Test Cases'!$B$2:$B$184,A6) | C6: =COUNTIFS('Test Cases'!$B$2:$B$184,$A6,'Test Cases'!$H$2:$H$184,"Pass") | D6: =COUNTIFS('Test Cases'!$B$2:$B$184,$A6,'Test Cases'!$H$2:$H$184,"Fail") | E6: =COUNTIFS('Test Cases'!$B$2:$B$184,$A6,'Test Cases'!$H$2:$H$184,"Blocked") | F6: =B6-C6-D6-E6 | G6: =IF(B6=0,0,(C6+D6+E6)/B6) | H6: =IF(C6+D6=0,0,C6/(C6+D6))
A7: Dispatcher | B7: =COUNTIF('Test Cases'!$B$2:$B$184,A7) | C7: =COUNTIFS('Test Cases'!$B$2:$B$184,$A7,'Test Cases'!$H$2:$H$184,"Pass") | D7: =COUNTIFS('Test Cases'!$B$2:$B$184,$A7,'Test Cases'!$H$2:$H$184,"Fail") | E7: =COUNTIFS('Test Cases'!$B$2:$B$184,$A7,'Test Cases'!$H$2:$H$184,"Blocked") | F7: =B7-C7-D7-E7 | G7: =IF(B7=0,0,(C7+D7+E7)/B7) | H7: =IF(C7+D7=0,0,C7/(C7+D7))
A8: Warehouse Crew | B8: =COUNTIF('Test Cases'!$B$2:$B$184,A8) | C8: =COUNTIFS('Test Cases'!$B$2:$B$184,$A8,'Test Cases'!$H$2:$H$184,"Pass") | D8: =COUNTIFS('Test Cases'!$B$2:$B$184,$A8,'Test Cases'!$H$2:$H$184,"Fail") | E8: =COUNTIFS('Test Cases'!$B$2:$B$184,$A8,'Test Cases'!$H$2:$H$184,"Blocked") | F8: =B8-C8-D8-E8 | G8: =IF(B8=0,0,(C8+D8+E8)/B8) | H8: =IF(C8+D8=0,0,C8/(C8+D8))
A9: Manager | B9: =COUNTIF('Test Cases'!$B$2:$B$184,A9) | C9: =COUNTIFS('Test Cases'!$B$2:$B$184,$A9,'Test Cases'!$H$2:$H$184,"Pass") | D9: =COUNTIFS('Test Cases'!$B$2:$B$184,$A9,'Test Cases'!$H$2:$H$184,"Fail") | E9: =COUNTIFS('Test Cases'!$B$2:$B$184,$A9,'Test Cases'!$H$2:$H$184,"Blocked") | F9: =B9-C9-D9-E9 | G9: =IF(B9=0,0,(C9+D9+E9)/B9) | H9: =IF(C9+D9=0,0,C9/(C9+D9))
A10: Admin | B10: =COUNTIF('Test Cases'!$B$2:$B$184,A10) | C10: =COUNTIFS('Test Cases'!$B$2:$B$184,$A10,'Test Cases'!$H$2:$H$184,"Pass") | D10: =COUNTIFS('Test Cases'!$B$2:$B$184,$A10,'Test Cases'!$H$2:$H$184,"Fail") | E10: =COUNTIFS('Test Cases'!$B$2:$B$184,$A10,'Test Cases'!$H$2:$H$184,"Blocked") | F10: =B10-C10-D10-E10 | G10: =IF(B10=0,0,(C10+D10+E10)/B10) | H10: =IF(C10+D10=0,0,C10/(C10+D10))
A11: Finance | B11: =COUNTIF('Test Cases'!$B$2:$B$184,A11) | C11: =COUNTIFS('Test Cases'!$B$2:$B$184,$A11,'Test Cases'!$H$2:$H$184,"Pass") | D11: =COUNTIFS('Test Cases'!$B$2:$B$184,$A11,'Test Cases'!$H$2:$H$184,"Fail") | E11: =COUNTIFS('Test Cases'!$B$2:$B$184,$A11,'Test Cases'!$H$2:$H$184,"Blocked") | F11: =B11-C11-D11-E11 | G11: =IF(B11=0,0,(C11+D11+E11)/B11) | H11: =IF(C11+D11=0,0,C11/(C11+D11))
A12: Customer | B12: =COUNTIF('Test Cases'!$B$2:$B$184,A12) | C12: =COUNTIFS('Test Cases'!$B$2:$B$184,$A12,'Test Cases'!$H$2:$H$184,"Pass") | D12: =COUNTIFS('Test Cases'!$B$2:$B$184,$A12,'Test Cases'!$H$2:$H$184,"Fail") | E12: =COUNTIFS('Test Cases'!$B$2:$B$184,$A12,'Test Cases'!$H$2:$H$184,"Blocked") | F12: =B12-C12-D12-E12 | G12: =IF(B12=0,0,(C12+D12+E12)/B12) | H12: =IF(C12+D12=0,0,C12/(C12+D12))
A13: Cross-cutting | B13: =COUNTIF('Test Cases'!$B$2:$B$184,A13) | C13: =COUNTIFS('Test Cases'!$B$2:$B$184,$A13,'Test Cases'!$H$2:$H$184,"Pass") | D13: =COUNTIFS('Test Cases'!$B$2:$B$184,$A13,'Test Cases'!$H$2:$H$184,"Fail") | E13: =COUNTIFS('Test Cases'!$B$2:$B$184,$A13,'Test Cases'!$H$2:$H$184,"Blocked") | F13: =B13-C13-D13-E13 | G13: =IF(B13=0,0,(C13+D13+E13)/B13) | H13: =IF(C13+D13=0,0,C13/(C13+D13))
A14: Data check | B14: =COUNTIF('Test Cases'!$B$2:$B$184,A14) | C14: =COUNTIFS('Test Cases'!$B$2:$B$184,$A14,'Test Cases'!$H$2:$H$184,"Pass") | D14: =COUNTIFS('Test Cases'!$B$2:$B$184,$A14,'Test Cases'!$H$2:$H$184,"Fail") | E14: =COUNTIFS('Test Cases'!$B$2:$B$184,$A14,'Test Cases'!$H$2:$H$184,"Blocked") | F14: =B14-C14-D14-E14 | G14: =IF(B14=0,0,(C14+D14+E14)/B14) | H14: =IF(C14+D14=0,0,C14/(C14+D14))
A15: All test cases | B15: =SUM(B6:B14) | C15: =SUM(C6:C14) | D15: =SUM(D6:D14) | E15: =SUM(E6:E14) | F15: =B15-C15-D15-E15 | G15: =IF(B15=0,0,(C15+D15+E15)/B15) | H15: =IF(C15+D15=0,0,C15/(C15+D15))
A17: Progress by case type
A18: Type | B18: Cases | C18: Pass | D18: Fail | E18: Blocked | F18: Not run | G18: % run | H18: Pass rate of those run
A19: Happy | B19: =COUNTIF('Test Cases'!$D$2:$D$184,A19) | C19: =COUNTIFS('Test Cases'!$D$2:$D$184,$A19,'Test Cases'!$H$2:$H$184,"Pass") | D19: =COUNTIFS('Test Cases'!$D$2:$D$184,$A19,'Test Cases'!$H$2:$H$184,"Fail") | E19: =COUNTIFS('Test Cases'!$D$2:$D$184,$A19,'Test Cases'!$H$2:$H$184,"Blocked") | F19: =B19-C19-D19-E19 | G19: =IF(B19=0,0,(C19+D19+E19)/B19) | H19: =IF(C19+D19=0,0,C19/(C19+D19))
A20: Wrong | B20: =COUNTIF('Test Cases'!$D$2:$D$184,A20) | C20: =COUNTIFS('Test Cases'!$D$2:$D$184,$A20,'Test Cases'!$H$2:$H$184,"Pass") | D20: =COUNTIFS('Test Cases'!$D$2:$D$184,$A20,'Test Cases'!$H$2:$H$184,"Fail") | E20: =COUNTIFS('Test Cases'!$D$2:$D$184,$A20,'Test Cases'!$H$2:$H$184,"Blocked") | F20: =B20-C20-D20-E20 | G20: =IF(B20=0,0,(C20+D20+E20)/B20) | H20: =IF(C20+D20=0,0,C20/(C20+D20))
A21: Edge | B21: =COUNTIF('Test Cases'!$D$2:$D$184,A21) | C21: =COUNTIFS('Test Cases'!$D$2:$D$184,$A21,'Test Cases'!$H$2:$H$184,"Pass") | D21: =COUNTIFS('Test Cases'!$D$2:$D$184,$A21,'Test Cases'!$H$2:$H$184,"Fail") | E21: =COUNTIFS('Test Cases'!$D$2:$D$184,$A21,'Test Cases'!$H$2:$H$184,"Blocked") | F21: =B21-C21-D21-E21 | G21: =IF(B21=0,0,(C21+D21+E21)/B21) | H21: =IF(C21+D21=0,0,C21/(C21+D21))
A22: Access | B22: =COUNTIF('Test Cases'!$D$2:$D$184,A22) | C22: =COUNTIFS('Test Cases'!$D$2:$D$184,$A22,'Test Cases'!$H$2:$H$184,"Pass") | D22: =COUNTIFS('Test Cases'!$D$2:$D$184,$A22,'Test Cases'!$H$2:$H$184,"Fail") | E22: =COUNTIFS('Test Cases'!$D$2:$D$184,$A22,'Test Cases'!$H$2:$H$184,"Blocked") | F22: =B22-C22-D22-E22 | G22: =IF(B22=0,0,(C22+D22+E22)/B22) | H22: =IF(C22+D22=0,0,C22/(C22+D22))
A23: "Wrong" = something goes wrong; "Access" = allowed or blocked by role.
A25: End-to-end journeys (each step counted)
A26: Journey | B26: Steps | C26: Pass | D26: Fail | E26: Blocked | F26: Not run | G26: % run | H26: Pass rate of those run
A27: E2E-01 | B27: =COUNTIF('E2E Journeys'!$A$2:$A$39,A27) | C27: =COUNTIFS('E2E Journeys'!$A$2:$A$39,$A27,'E2E Journeys'!$G$2:$G$39,"Pass") | D27: =COUNTIFS('E2E Journeys'!$A$2:$A$39,$A27,'E2E Journeys'!$G$2:$G$39,"Fail") | E27: =COUNTIFS('E2E Journeys'!$A$2:$A$39,$A27,'E2E Journeys'!$G$2:$G$39,"Blocked") | F27: =B27-C27-D27-E27 | G27: =IF(B27=0,0,(C27+D27+E27)/B27) | H27: =IF(C27+D27=0,0,C27/(C27+D27))
A28: E2E-02 | B28: =COUNTIF('E2E Journeys'!$A$2:$A$39,A28) | C28: =COUNTIFS('E2E Journeys'!$A$2:$A$39,$A28,'E2E Journeys'!$G$2:$G$39,"Pass") | D28: =COUNTIFS('E2E Journeys'!$A$2:$A$39,$A28,'E2E Journeys'!$G$2:$G$39,"Fail") | E28: =COUNTIFS('E2E Journeys'!$A$2:$A$39,$A28,'E2E Journeys'!$G$2:$G$39,"Blocked") | F28: =B28-C28-D28-E28 | G28: =IF(B28=0,0,(C28+D28+E28)/B28) | H28: =IF(C28+D28=0,0,C28/(C28+D28))
A29: E2E-03 | B29: =COUNTIF('E2E Journeys'!$A$2:$A$39,A29) | C29: =COUNTIFS('E2E Journeys'!$A$2:$A$39,$A29,'E2E Journeys'!$G$2:$G$39,"Pass") | D29: =COUNTIFS('E2E Journeys'!$A$2:$A$39,$A29,'E2E Journeys'!$G$2:$G$39,"Fail") | E29: =COUNTIFS('E2E Journeys'!$A$2:$A$39,$A29,'E2E Journeys'!$G$2:$G$39,"Blocked") | F29: =B29-C29-D29-E29 | G29: =IF(B29=0,0,(C29+D29+E29)/B29) | H29: =IF(C29+D29=0,0,C29/(C29+D29))
A30: E2E-04 | B30: =COUNTIF('E2E Journeys'!$A$2:$A$39,A30) | C30: =COUNTIFS('E2E Journeys'!$A$2:$A$39,$A30,'E2E Journeys'!$G$2:$G$39,"Pass") | D30: =COUNTIFS('E2E Journeys'!$A$2:$A$39,$A30,'E2E Journeys'!$G$2:$G$39,"Fail") | E30: =COUNTIFS('E2E Journeys'!$A$2:$A$39,$A30,'E2E Journeys'!$G$2:$G$39,"Blocked") | F30: =B30-C30-D30-E30 | G30: =IF(B30=0,0,(C30+D30+E30)/B30) | H30: =IF(C30+D30=0,0,C30/(C30+D30))
A31: E2E-05 | B31: =COUNTIF('E2E Journeys'!$A$2:$A$39,A31) | C31: =COUNTIFS('E2E Journeys'!$A$2:$A$39,$A31,'E2E Journeys'!$G$2:$G$39,"Pass") | D31: =COUNTIFS('E2E Journeys'!$A$2:$A$39,$A31,'E2E Journeys'!$G$2:$G$39,"Fail") | E31: =COUNTIFS('E2E Journeys'!$A$2:$A$39,$A31,'E2E Journeys'!$G$2:$G$39,"Blocked") | F31: =B31-C31-D31-E31 | G31: =IF(B31=0,0,(C31+D31+E31)/B31) | H31: =IF(C31+D31=0,0,C31/(C31+D31))
A32: E2E-06 | B32: =COUNTIF('E2E Journeys'!$A$2:$A$39,A32) | C32: =COUNTIFS('E2E Journeys'!$A$2:$A$39,$A32,'E2E Journeys'!$G$2:$G$39,"Pass") | D32: =COUNTIFS('E2E Journeys'!$A$2:$A$39,$A32,'E2E Journeys'!$G$2:$G$39,"Fail") | E32: =COUNTIFS('E2E Journeys'!$A$2:$A$39,$A32,'E2E Journeys'!$G$2:$G$39,"Blocked") | F32: =B32-C32-D32-E32 | G32: =IF(B32=0,0,(C32+D32+E32)/B32) | H32: =IF(C32+D32=0,0,C32/(C32+D32))
A33: Journey names are on the E2E Journeys sheet.
A35: Defects
A36: Severity | B36: Logged | C36: Open | D36: Closed
A37: Critical | B37: =COUNTIF(Defects!$C$2:$C$101,A37) | C37: =COUNTIFS(Defects!$C$2:$C$101,$A37,Defects!$K$2:$K$101,"Open")+COUNTIFS(Defects!$C$2:$C$101,$A37,Defects!$K$2:$K$101,"In progress")+COUNTIFS(Defects!$C$2:$C$101,$A37,Defects!$K$2:$K$101,"Fixed")+COUNTIFS(Defects!$C$2:$C$101,$A37,Defects!$K$2:$K$101,"Retest") | D37: =COUNTIFS(Defects!$C$2:$C$101,$A37,Defects!$K$2:$K$101,"Closed")+COUNTIFS(Defects!$C$2:$C$101,$A37,Defects!$K$2:$K$101,"Not a defect")
A38: Major | B38: =COUNTIF(Defects!$C$2:$C$101,A38) | C38: =COUNTIFS(Defects!$C$2:$C$101,$A38,Defects!$K$2:$K$101,"Open")+COUNTIFS(Defects!$C$2:$C$101,$A38,Defects!$K$2:$K$101,"In progress")+COUNTIFS(Defects!$C$2:$C$101,$A38,Defects!$K$2:$K$101,"Fixed")+COUNTIFS(Defects!$C$2:$C$101,$A38,Defects!$K$2:$K$101,"Retest") | D38: =COUNTIFS(Defects!$C$2:$C$101,$A38,Defects!$K$2:$K$101,"Closed")+COUNTIFS(Defects!$C$2:$C$101,$A38,Defects!$K$2:$K$101,"Not a defect")
A39: Minor | B39: =COUNTIF(Defects!$C$2:$C$101,A39) | C39: =COUNTIFS(Defects!$C$2:$C$101,$A39,Defects!$K$2:$K$101,"Open")+COUNTIFS(Defects!$C$2:$C$101,$A39,Defects!$K$2:$K$101,"In progress")+COUNTIFS(Defects!$C$2:$C$101,$A39,Defects!$K$2:$K$101,"Fixed")+COUNTIFS(Defects!$C$2:$C$101,$A39,Defects!$K$2:$K$101,"Retest") | D39: =COUNTIFS(Defects!$C$2:$C$101,$A39,Defects!$K$2:$K$101,"Closed")+COUNTIFS(Defects!$C$2:$C$101,$A39,Defects!$K$2:$K$101,"Not a defect")
A40: "Open" here means logged but not yet Closed or marked Not a defect.
A42: Proposed acceptance rule
A43: All Critical and Major cases pass, no open Critical defects, and every Minor defect has an owner.
A44: Open Critical defects right now: | C44: =C37
A45: Cases failed right now: | C45: =D15

Sheet Test Cases
A1: ID | B1: Role (point of view) | C1: Area | D1: Type | E1: Scenario | F1: Steps | G1: Expected result | H1: Status | I1: Tester | J1: Date tested | K1: Defect ID | L1: Notes
A2: ACC-01 | B2: Everyone | C2: Sign-in, access and shared tools | D2: Happy | E2: Each role signs in and lands in the right place | F2: 1. Sign in as Dispatcher, note the page and the top bar. 2. Sign out. Repeat for Warehouse Crew, Manager, Admin, Finance. | G2: Dispatcher and Warehouse Crew land on My Tasks. Manager, Admin and Finance land on Dashboard. The top bar always reads "Name · Role" (for example "Grace Tan · Manager"). | H2: Pass | I2: Claude (automated, Playwright) | J2: 46294 | L2: Automated pass, 10 checks.
A3: ACC-02 | B3: Everyone | C3: Sign-in, access and shared tools | D3: Access | E3: Sidebar shows only what the role may use | F3: Sign in as each role and read the left menu. | G3: Dispatcher: My Tasks, Dashboard, Customers, Inquiries & Quotations, Shipment Jobs. Warehouse Crew: My Tasks, Shipment Jobs. Manager: Dashboard, Customers, Inquiries & Quotations, Shipment Jobs, Audit Trail. Admin: the same as Manager plus Users & Roles. Finance: Dashboard, Shipment Jobs, Audit Trail. Nothing extra is shown greyed out. | H3: Pass | I3: Claude (automated, Playwright) | J3: 46294 | L3: Automated pass, 10 checks.
A4: ACC-03 | B4: Everyone | C4: Sign-in, access and shared tools | D4: Wrong | E4: Typing the address of a page the role may not open | F4: 1. As Manager, change the address ending to #/users and press Enter. 2. As Dispatcher, use #/audit. 3. As Warehouse Crew, use #/dashboard. 4. As Finance, use #/customers. | G4: Each time you see "Not available for your role" and a sentence naming the module. No data from that page is shown. | H4: Pass | I4: Claude (automated, Playwright) | J4: 46294 | L4: Automated pass, 12 checks.
A5: ACC-04 | B5: Everyone | C5: Sign-in, access and shared tools | D5: Wrong | E5: Opening the app without signing in | F5: 1. Refresh the page. 2. In the address bar type #/dashboard after the file name and press Enter. | G5: You are taken to the sign-in screen. No dashboard content flashes. | H5: Pass | I5: Claude (automated, Playwright) | J5: 46294 | L5: Automated pass, 5 checks.
A6: ACC-05 | B6: Everyone | C6: Sign-in, access and shared tools | D6: Wrong | E6: Going back after signing out | F6: 1. Sign in as any role and open a job. 2. Sign out. 3. Press the browser Back button several times. | G6: You always end on the sign-in screen. No protected page is shown. | H6: Pass | I6: Claude (automated, Playwright) | J6: 46294 | L6: Automated pass, 3 checks.
A7: ACC-06 | B7: Everyone | C7: Sign-in, access and shared tools | D7: Happy | E7: Global search with the keyboard | F7: 1. As Manager press Ctrl+K (Cmd+K on Mac). 2. Type blue. 3. Press the down arrow, then Enter. 4. Press Ctrl+K again and press Esc. | G7: A "Jump to a job or customer" box opens. blue lists the customer BlueWave Distribution Corp. and jobs for that customer. Enter opens the highlighted item. Esc closes the box. | H7: Pass | I7: Claude (automated, Playwright) | J7: 46294 | L7: Automated pass, 6 checks.
A8: ACC-07 | B8: Everyone | C8: Sign-in, access and shared tools | D8: Wrong | E8: Search with nothing found | F8: 1. Press Ctrl+K. 2. Type zzzz. | G8: The list says No jobs or customers match "zzzz". Nothing breaks. | H8: Pass | I8: Claude (automated, Playwright) | J8: 46294 | L8: Automated pass, 1 checks.
A9: ACC-08 | B9: Everyone | C9: Sign-in, access and shared tools | D9: Access | E9: Search only offers what the role may open | F9: 1. As Finance, press Ctrl+K and type sample. 2. As Warehouse Crew (Ben), press Ctrl+K with the box empty, then type SJ-2026-00088. | G9: Finance sees jobs but no customers. Ben sees only his four assigned jobs and no result for SJ-2026-00088. | H9: Pass | I9: Claude (automated, Playwright) | J9: 46294 | L9: Automated pass, 3 checks.
A10: ACC-09 | B10: Everyone | C10: Sign-in, access and shared tools | D10: Happy | E10: Notifications | F10: Click the bell icon in the top bar. | G10: A "Notifications" panel slides in showing an illustrative overdue-task email (task "Lodge customs entry" on SJ-2026-00082, addressed to Cathy Lim) and a warning that it is a mock. Close it with the X. | H10: Pass | I10: Claude (automated, Playwright) | J10: 46294 | L10: Automated pass, 6 checks.
A11: ACC-10 | B11: Everyone | C11: Sign-in, access and shared tools | D11: Happy | E11: Demo role switch | F11: 1. Sign in as Manager, open a job. 2. Avatar menu, Demo: switch role, choose Finance. | G11: The top bar and sidebar change to Finance. The job stays open but shows only the Overview and Charges tabs. | H11: Pass | I11: Claude (automated, Playwright) | J11: 46294 | L11: Automated pass, 4 checks.
A12: ACC-11 | B12: Everyone | C12: Sign-in, access and shared tools | D12: Edge | E12: Switching role while on a page the new role cannot open | F12: 1. As Admin, open Users & Roles. 2. Switch role to Manager. | G12: You are moved to the Dashboard instead of an error page. | H12: Pass | I12: Claude (automated, Playwright) | J12: 46294 | L12: Automated pass, 3 checks.
A13: ACC-12 | B13: Everyone | C13: Sign-in, access and shared tools | D13: Wrong | E13: Job or page that does not exist | F13: 1. Signed in as Manager, go to #/jobs/SJ-2026-99999. 2. Go to #/customers/CUST-99. | G13: "Job not found." and "Customer not found." messages. No crash. | H13: Pass | I13: Claude (automated, Playwright) | J13: 46294 | L13: Automated pass, 2 checks.
... A69: WHC-04 | B69: Warehouse Crew | C69: Field work | D69: Wrong | E69: Opening a job that is not yours | F69: Go to #/jobs/SJ-2026-00088. | G69: "Not available for Warehouse Crew" and "SJ-2026-00088 is not assigned to you." No job details shown. | H69: Pass | I69: Claude (automated, Playwright) | J69: 46294 | L69: Automated pass, 3 checks.
A70: WHC-05 | B70: Warehouse Crew | C70: Field work | D70: Access | E70: Tasks tab is limited to my own tasks | F70: Open SJ-2026-00077, Tasks tab. | G70: Note "Showing your tasks only." Only Ben's two tasks appear (Deliver to consignee, Return empty container). There is no Reassign button. On a job where Ben has no open tasks the table says "No tasks assigned to you on this job." | H70: Fail | I70: Claude (automated, Playwright) | J70: 46294 | K70: D-003 | L70: Automated FAIL: Expected "No tasks assigned to you on this job." on a job where Ben has no open tasks, but it never appears: Ben can only open jobs where he owns a task, and on SJ-2026-00101 (all his tasks done) the two Completed tasks are still listed. That empty state cannot be reached with the sample data.
A71: WHC-06 | B71: Warehouse Crew | C71: Field work | D71: Happy | E71: Confirm a delivery with proof | F71: 1. On My Tasks click Confirm + POD for SJ-2026-00077. 2. Received by J. Ramos (Receiving), attach a file as proof of delivery, damage switch off. 3. Confirm delivery. | G71: Message "Delivery confirmed in full." The job becomes Delivered. The Deliveries to confirm list now says "Nothing out for delivery right now." On the job's Delivery tab you see "Delivered in full", the date, the receiver, and your file name as the Proof of Delivery. | H71: Pass | I71: Claude (automated, Playwright) | J71: 46294 | L71: Automated pass, 9 checks.
A72: WHC-07 | B72: Warehouse Crew | C72: Field work | D72: Wrong | E72: Confirm without who received it | F72: Open the same drawer, leave Received by empty, submit. | G72: Message "Enter who received the delivery." Job stays Out for Delivery. | H72: Pass | I72: Claude (automated, Playwright) | J72: 46294 | L72: Automated pass, 2 checks. Note: Needed a page refresh first: WHC-06 already delivers SJ-2026-00077, so "the same drawer" is not available on the same page load
A73: WHC-08 | B73: Warehouse Crew | C73: Field work | D73: Wrong | E73: Confirm without proof of delivery | F73: Fill Received by but attach nothing, submit. | G73: Message "Attach the proof of delivery before confirming." Job stays Out for Delivery. | H73: Pass | I73: Claude (automated, Playwright) | J73: 46294 | L73: Automated pass, 2 checks.
A74: WHC-09 | B74: Warehouse Crew | C74: Field work | D74: Wrong | E74: Delivered with damage (Refresh first) | F74: 1. Repeat WHC-06 but switch Damage or incomplete delivery on and describe Two pallets crushed. 2. Confirm. | G74: Message "Delivery confirmed — damage reported." The Delivery tab shows a red "Damage / incomplete delivery reported" box with your description. The job is Delivered. (Later, the billing checklist must stay blocked, see MGR-18.) | H74: Pass | I74: Claude (automated, Playwright) | J74: 46294 | L74: Automated pass, 5 checks.
A75: WHC-10 | B75: Warehouse Crew | C75: Field work | D75: Wrong | E75: Delivery cannot be confirmed too early | F75: 1. Open SJ-2026-00095 (Documentation), Delivery tab. | G75: Blue note "Not out for delivery yet: Delivery can be confirmed once the job is Out for Delivery. It is currently Documentation." No form. | H75: Pass | I75: Claude (automated, Playwright) | J75: 46294 | L75: Automated pass, 3 checks.
A76: WHC-11 | B76: Warehouse Crew | C76: Field work | D76: Happy | E76: Complete a delivery task with proof | F76: On SJ-2026-00077 Tasks, Complete on "Deliver to consignee", attach a file, note Left at dock 2, Mark complete. | G76: Status Completed, View evidence appears and shows Completed by Ben Santos. | H76: Pass | I76: Claude (automated, Playwright) | J76: 46294 | L76: Automated pass, 2 checks.
A77: WHC-12 | B77: Warehouse Crew | C77: Field work | D77: Wrong | E77: Complete without proof | F77: Try the same on another proof-required task (SJ-2026-00065 "Deliver to consignee") without a file. | G77: Message "Attach the completion evidence first. This task requires it." | H77: Pass | I77: Claude (automated, Playwright) | J77: 46294 | L77: Automated pass, 1 checks.
A78: WHC-13 | B78: Warehouse Crew | C78: Field work | D78: Happy | E78: Return the empty container (act as Rico, see 2.2) | F78: 1. On the jobs list note SJ-2026-00070 shows the flag "Free detention: 2d left". 2. Open it, Tasks tab, Complete "Return empty container" (no proof needed). 3. Go back to the jobs list. | G78: Task Completed. The detention flag is gone from SJ-2026-00070. | H78: Pass | I78: Claude (automated, Playwright) | J78: 46294 | L78: Automated pass, 4 checks.
A79: WHC-14 | B79: Warehouse Crew | C79: Field work | D79: Access | E79: Documents: upload only | F79: 1. Open SJ-2026-00095 Documents. | G79: Import Permit (Missing) has Upload; Certificate of Origin (Rejected) has Replace; Bill of Lading (Pending Review) has no Review button. Uploading works as in DSP-41 (a first upload becomes version 1). | H79: Pass | I79: Claude (automated, Playwright) | J79: 46294 | L79: Automated pass, 5 checks.
A80: WHC-15 | B80: Warehouse Crew | C80: Field work | D80: Happy | E80: Raise an exception from the floor | F80: On SJ-2026-00077 Exceptions, Raise exception, category Damage, reason Container door seal broken. | G80: Job becomes Exception Hold, exception is Pending Approval, and there is no Review button for the crew. Message "Exception raised — job on hold." | H80: Pass | I80: Claude (automated, Playwright) | J80: 46294 | L80: Automated pass, 4 checks.
A81: WHC-16 | B81: Warehouse Crew | C81: Field work | D81: Access | E81: No money, no admin | F81: 1. Open any assigned job. 2. Go to #/jobs/SJ-2026-00077/charges. | G81: Tabs: Overview, Tasks, Documents, Exceptions, Delivery. No Charges tab. The address shows Overview. No charges, funds or margin anywhere. | H81: Pass | I81: Claude (automated, Playwright) | J81: 46294 | L81: Automated pass, 3 checks.
A82: WHC-17 | B82: Warehouse Crew | C82: Field work | D82: Access | E82: Dashboard is not for the crew | F82: Go to #/dashboard. | G82: "Not available for Warehouse Crew". | H82: Pass | I82: Claude (automated, Playwright) | J82: 46294 | L82: Automated pass, 1 checks.
... A168: XC-01 | B168: Cross-cutting | C168: Cross-cutting checks | D168: Happy | E168: Layout at four screen widths | F168: For sign-in, Dashboard, a job's Charges tab, Billing Summary and the tracking page, test at 1440, 1024, 768 and 400 px wide. | G168: No sideways scrolling of the page, no clipped or overlapping text. At 960 px and below the sidebar shrinks to an icon rail; below 640 px it becomes a bottom bar. Wide tables scroll inside their own box. | H168: Pass | I168: Claude (automated, Playwright) | J168: 46294 | L168: Automated pass, 1 checks. Note: At 400px the 9-stage milestone track and the customs sub-track scroll sideways inside their own card (allowed) but show no scroll cue, and the current stage can start off-screen | Screenshots of all 20 combinations saved for review
A169: XC-02 | B169: Cross-cutting | C169: Cross-cutting checks | D169: Access | E169: Keyboard only | F169: Using only Tab, Shift+Tab, Enter and Space: sign in, open a job, open a drawer, close it. | G169: Every control is reachable in a sensible order, focus is always visible, and no step needs a mouse. | H169: Fail | I169: Claude (automated, Playwright) | J169: 46294 | K169: D-001 | L169: Automated FAIL: Keyboard-only use: "every control is reachable in a sensible order... no step needs a mouse": expected "" but got "Job rows are not keyboard-focusable (the row is a click target only; each row has just a ⋮ button) ;; Opening the ⋮ menu with Enter does not move focus into the menu ;; The only keyboard route to a job (⋮ menu, "Open tasks") needs 12 Tab presses to reach the menu item (menu is at the end of the page) ;; Inquiry rows have no focusable control at all, so an inquiry cannot be opened from the list with the keyboard ;; Opening a drawer (New customer) leaves focus on the trigger button instead of moving into the drawer ;; The first drawer control needs 7 Tab presses to reach (drawer is at the end of the page; focus is not trapped or moved)"
A170: XC-03 | B170: Cross-cutting | C170: Cross-cutting checks | D170: Access | E170: Reduced motion | F170: Turn on "reduce motion" in your operating system, reload, open SJ-2026-00120 Charges and a tracking page. | G170: The warning banner, ledger rows, route line and timeline do not animate. | H170: Pass | I170: Claude (automated, Playwright) | J170: 46294 | L170: Automated pass, 2 checks.
A171: XC-04 | B171: Cross-cutting | C171: Cross-cutting checks | D171: Access | E171: Status is never colour alone | F171: Scan status tags (job status, task, document, funds, customer timeline). | G171: Every status has an icon and a word next to its colour. Negative amounts also carry a minus sign. | H171: Pass | I171: Claude (automated, Playwright) | J171: 46294 | L171: Automated pass, 4 checks.
A172: XC-05 | B172: Cross-cutting | C172: Cross-cutting checks | D172: Happy | E172: Everything mock is labelled | F172: Look at Dashboard, Billing Summary, Charges footnote, tracking page footer, sign-in. | G172: Illustrative or mock wording is visible ("Illustrative data", "Mock document", "Mockup only"). No real company, person or price appears. The Billing Summary is never titled an invoice. | H172: Pass | I172: Claude (automated, Playwright) | J172: 46294 | L172: Automated pass, 6 checks.
A173: XC-06 | B173: Cross-cutting | C173: Cross-cutting checks | D173: Happy | E173: Every change leaves an audit entry | F173: Perform each action in the table below on any suitable job, then read the job's Status history (or Audit Trail). | G173: One entry per action, with the wording below and the real signed-in person as "Name (Role)". | H173: Pass | I173: Claude (automated, Playwright) | J173: 46294 | L173: Automated pass, 43 checks.
A174: XC-07 | B174: Cross-cutting | C174: Cross-cutting checks | D174: Wrong | E174: No script errors | F174: Open the browser developer tools console and run a long session (any journey in section 11). | G174: No red errors. No browser pop-up dialogs (alert, confirm) ever appear. | H174: Pass | I174: Claude (automated, Playwright) | J174: 46294 | L174: Automated pass, 2 checks. Note: Covers every case run in this session, including the long E2E journeys when the full suite is run in one go
A175: XC-08 | B175: Cross-cutting | C175: Cross-cutting checks | D175: Happy | E175: Messages behave | F175: Trigger a success and an error message. | G175: Messages appear bottom-right, are readable, and disappear after a few seconds without blocking anything. | H175: Pass | I175: Claude (automated, Playwright) | J175: 46294 | L175: Automated pass, 5 checks.
A176: XC-09 | B176: Cross-cutting | C176: Cross-cutting checks | D176: Edge | E176: Refresh restores the sample data | F176: After changing things, refresh and sign in again. | G176: All original sample data is back. (This is expected; nothing is saved.) | H176: Pass | I176: Claude (automated, Playwright) | J176: 46294 | L176: Automated pass, 5 checks.
A177: DAT-01 | B177: Data check | C177: Data sanity checks | D177: Happy | E177: SJ-2026-00101 matches its PDF | G177: Charges ₱132,000.00, ₱18,400.00, ₱3,500.00 (total ₱153,900.00); quotation ₱174,500.00 (QT-2026-0041 v3). | H177: Pass | I177: Claude (automated, Playwright) | J177: 46294 | L177: Automated pass, 6 checks.
A178: DAT-02 | B178: Data check | C178: Data sanity checks | D178: Happy | E178: The five money jobs add up | G178: Money in · Money spent · Left over · Our fees · Final balance SJ-2026-00060 · ₱175,000.00 · ₱150,400.00 · ₱24,600.00 · ₱8,500.00 (₱3,500.00 fee + ₱5,000.00 markup) · Refund due to client ₱16,100.00 SJ-2026-00101 · ₱140,000.00 · ₱150,400.00 · −₱10,400.00 · ₱3,500.00 · Balance to bill client ₱13,900.00 SJ-2026-00050 · ₱104,700.00 · ₱102,200.00 · ₱2,500.00 · ₱2,500.00 · Fully settled SJ-2026-00070 · ₱160,000.00 · ₱145,700.00 · ₱14,300.00 · ₱3,500.00 · Refund due ₱10,800.00 (provisional) SJ-2026-00120 · ₱106,000.00 · ₱96,000.00 · ₱10,000.00 · none yet · Not worked out before delivery; short by ₱8,400.00 for the ₱18,400.00 duty | H178: Pass | I178: Claude (automated, Playwright) | J178: 46294 | L178: Automated pass, 28 checks.
A179: DAT-03 | B179: Data check | C179: Data sanity checks | D179: Happy | E179: Dashboard counts equal their lists | G179: Each card equals the number of rows in its table (overdue 1, missing/rejected 7, exceptions 1, short on funds 1). The status ring total equals the number of jobs (12; 11 active plus 1 closed). | H179: Pass | I179: Claude (automated, Playwright) | J179: 46294 | L179: Automated pass, 8 checks.
A180: DAT-04 | B180: Data check | C180: Data sanity checks | D180: Happy | E180: Task owners fit the role | G180: Dispatcher owns commercial and customs tasks: Verify shipment documents complete, Lodge customs entry, Pay duties and assessment, Secure delivery order, Book delivery truck. Warehouse Crew own physical tasks: Deliver to consignee, Return empty container. The dispatcher owning a job's tasks is the dispatcher of that customer. | H180: Pass | I180: Claude (automated, Playwright) | J180: 46294 | L180: Automated pass, 1 checks.
...

Sheet E2E Journeys
A1: Journey | B1: Journey name | C1: Step | D1: Who | E1: Do this | F1: Checkpoint (expected) | G1: Status | H1: Tester | I1: Date tested | J1: Defect ID | K1: Notes
A2: E2E-01 | B2: Happy path: from first inquiry to money settled, with the customer watching | C2: 1 | D2: Dispatcher (Ana) | E2: Open INQ-2026-0043 (New). Click Create quotation. | F2: Quotation QT-2026-0044 at ₱150,000.00, status Pending customer approval. Inquiry now Quoted. | G2: Pass | H2: Claude (automated, Playwright) | I2: 46294 | K2: Automated pass, 5 checks.
A3: E2E-01 | B3: Happy path: from first inquiry to money settled, with the customer watching | C3: 2 | D3: Dispatcher | E3: Record customer approval / conforme as Liza Fernandez, then Convert to Shipment Job, then Create Shipment Job. | F3: Job SJ-2026-00123 exists for Pacific Rim, status Booked, five documents Missing. | G3: Pass | H3: Claude (automated, Playwright) | I3: 46294 | K3: Automated pass, 4 checks.
A4: E2E-01 | B4: Happy path: from first inquiry to money settled, with the customer watching | C4: 3 | D4: Customer | E4: Open the customer tracking page and enter SJ-2026-00123. | F4: Headline Booked, "Your booking is confirmed.", "Estimated arrival to be confirmed". | G4: Pass | H4: Claude (automated, Playwright) | I4: 46294 | K4: Automated pass, 3 checks.
A5: E2E-01 | B5: Happy path: from first inquiry to money settled, with the customer watching | C5: 4 | D5: Dispatcher | E5: Documents tab: Upload each of the five documents, then Review, Approve each. On Tasks, complete "Verify shipment documents complete" with a file. | F5: All five Approved. Dashboard "Missing / rejected docs" back to 5 for Ana. | G5: Pass | H5: Claude (automated, Playwright) | I5: 46294 | K5: Automated pass, 2 checks.
A6: E2E-01 | B6: Happy path: from first inquiry to money settled, with the customer watching | C6: 5 | D6: Dispatcher | E6: Update status three times: Documentation, Sailed, Arrived at Port. | F6: Customer page after Sailed reads "On the water", after Arrived at Port reads "Arrived at port". | G6: Pass | H6: Claude (automated, Playwright) | I6: 46294 | K6: Automated pass, 2 checks.
A7: E2E-01 | B7: Happy path: from first inquiry to money settled, with the customer watching | C7: 6 | D7: Dispatcher | E7: Update status to Customs Clearance. In the Customs panel click Advance customs stage six times: Lodged, Assessment Pending, Payment Pending (choose Top1Movers), Payment Completed, Release Pending, Released. | F7: Panel track ends at Released. Customer page shows "Customs stage:" moving along and never shows the "Delayed" tag. | G7: Pass | H7: Claude (automated, Playwright) | I7: 46294 | K7: Automated pass, 2 checks.
A8: E2E-01 | B8: Happy path: from first inquiry to money settled, with the customer watching | C8: 7 | D8: Dispatcher | E8: Complete tasks "Lodge customs entry" and "Pay duties and assessment" (files needed), "Secure delivery order" and "Book delivery truck". Then Update status to Out for Delivery. | F8: Job is Out for Delivery. Delivered cannot be picked from the list (gate note). | G8: Pass | H8: Claude (automated, Playwright) | I8: 46294 | K8: Automated pass, 2 checks.
A9: E2E-01 | B9: Happy path: from first inquiry to money settled, with the customer watching | C9: 8 | D9: Warehouse Crew (Ben) | E9: My Tasks, Confirm + POD on SJ-2026-00123 with receiver J. Ramos and a file. Then complete "Deliver to consignee" (file) and "Return empty container". | F9: Message "Delivery confirmed in full." Job Delivered. Customer page shows Delivered, the delivery panel and proof of delivery. | G9: Pass | H9: Claude (automated, Playwright) | I9: 46294 | K9: Automated pass, 4 checks.
A10: E2E-01 | B10: Happy path: from first inquiry to money settled, with the customer watching | C10: 9 | D10: Manager (Grace) | E10: Charges, Add funds received 200000. Add charge: Ocean freight Freight Reimbursable 120000 paid, Customs duty Duties & Taxes Reimbursable 25000 paid, Documentation fee Fees Service fee 3500. Attach a file to each paid charge. | F10: Money in ₱200,000.00, Money spent ₱145,000.00, Left over ₱55,000.00. Final balance "Refund due to client: ₱51,500.00". Cost & margin: quoted ₱150,000.00, margin ₱3,500.00, 2.4%, "Within quote". No receipt-missing tags. All six checklist lines Done. | G10: Pass | H10: Claude (automated, Playwright) | I10: 46294 | K10: Automated pass, 10 checks.
A11: E2E-01 | B11: Happy path: from first inquiry to money settled, with the customer watching | C11: 10 | D11: Manager | E11: Click Mark Ready for Finance. | F11: Message "SJ-2026-00123 is billing ready — handed to Finance." Status Billing Ready. | G11: Pass | H11: Claude (automated, Playwright) | I11: 46294 | K11: Automated pass, 2 checks.
A12: E2E-01 | B12: Happy path: from first inquiry to money settled, with the customer watching | C12: 11 | D12: Finance (Paolo) | E12: Open the job's Charges, then Open Billing Summary. | F12: Summary shows "Mock document", the split (Reimbursable ₱145,000.00, Service fees ₱3,500.00), Money in/spent/left over and Refund due to client ₱51,500.00. Every control is read-only. | G12: Pass | H12: Claude (automated, Playwright) | I12: 46294 | K12: Automated pass, 7 checks.
A13: E2E-01 | B13: Happy path: from first inquiry to money settled, with the customer watching | C13: 12 | D13: Manager | E13: Update status to Closed. | F13: Status Closed. Customer page still says Delivered. | G13: Pass | H13: Claude (automated, Playwright) | I13: 46294 | K13: Automated pass, 2 checks.
... A39: E2E-06 | B39: Something went wrong: a person leaves, work is handed on | C39: 4 | D39: Admin | E39: Turn Cathy Lim back on. | F39: "Cathy Lim is now active." | G39: Pass | H39: Claude (automated, Playwright) | I39: 46294 | K39: Automated pass, 1 checks.

Sheet Defects
A1: Defect ID | B1: Test case / step | C1: Severity | D1: Title | E1: What you did | F1: What you expected | G1: What happened | H1: Screenshot / link | I1: Reported by | J1: Date | K1: Status | L1: Owner | M1: Notes
A2: D-001 | B2: XC-02 | C2: Major | D2: Keyboard-only use: rows and drawers cannot be operated in a sensible order | E2: Signed in and moved around using only Tab / Shift+Tab / Enter / Space; tried to open a job, an inquiry and a drawer (New customer). | F2: Every control is reachable in a sensible order, focus is visible, no step needs a mouse. | G2: Focus ring is visible and sign-in works by keyboard. But: job rows and inquiry rows are click-only (no tabindex, no link), so an inquiry cannot be opened from its list by keyboard at all, and a job only via the row menu; the row menu opens at the end of the page (focus stays on the button, 12 Tab presses to reach "Open tasks"); opening a drawer leaves focus on the trigger button and the first drawer control is 7 Tab presses away. | H2: n/a (behaviour / data; see Notes) | I2: Claude (automated, Playwright) | J2: 46294 | K2: Open | M2: Suggest: make rows real links or add tabindex + Enter handler; move focus into menus and drawers on open and return it on close.
A3: D-002 | B3: DAT-06 | C3: Minor | D3: Sample data has activity dated before the job was created | E3: Read every job's history, deposits, payments and task completion dates against its "Job created" date. | F3: No job has activity before it was created; history starts with "Job created"; deposits and payments fall between creation and today. | G3: SJ-2026-00101: history starts with "Funds received" (10 Sep) and the ₱135,000.00 deposit is dated 10 Sep, but the job was created 13 Sep. Also tasks show "Completed on" dates earlier than job creation on SJ-2026-00101 (10-12 Sep vs created 13 Sep), 00088 (10 Sep vs 16 Sep), 00082 (10 Sep vs 12 Sep), 00130 (10-11 Sep vs 14 Sep), 00065 (10-11 Sep vs 13 Sep) and 00120 (10-11 Sep vs 14 Sep). | H3: n/a (behaviour / data; see Notes) | I3: Claude (automated, Playwright) | J3: 46294 | K3: Open | M3: MGR-14 in the plan itself expects "completed on 2026-09-10" for SJ-2026-00101, so the plan and the rule conflict. Fix the data (or the rule).
A4: D-003 | B4: WHC-05 | C4: Minor | D4: Warehouse Crew empty-task message cannot be reached | E4: Opened the Tasks tab on all four of Ben Santos's jobs. | F4: On a job where Ben has no open tasks the table says "No tasks assigned to you on this job." | G4: Ben can only open jobs where he owns a task, and the Tasks tab lists his tasks whether open or completed. On SJ-2026-00101 (all his tasks done) the two Completed tasks are still shown, so the empty message never appears with the sample data. | H4: n/a (behaviour / data; see Notes) | I4: Claude (automated, Playwright) | J4: 46294 | K4: Open | M4: Either the expected result is wrong or the tab should hide Completed tasks. Decision needed.
A5: D-004
A6: D-005
A7: D-006
A8: D-007
A9: D-008
A10: D-009
A11: D-010
A12: D-011
A13: D-012
A14: D-013
A15: D-014
A16: D-015
... A101: D-100

Sheet Test Data
A1: Test data: what you test against
A3: People (demo accounts)
A4: Role | B4: Person | C4: Lands on | D4: Owns / covers
A5: Dispatcher | B5: Ana Cruz | C5: My Tasks | D5: Customers: Sample Trading Co., Pacific Rim Logistics Partners, Meridian Import Export Ltd.
A6: Dispatcher | B6: Cathy Lim | C6: My Tasks | D6: Customers: Golden Harvest Exports Inc., BlueWave Distribution Corp.
A7: Warehouse Crew | B7: Ben Santos | C7: My Tasks | D7: Odd-numbered jobs: SJ-2026-00101, 00095, 00077, 00065
A8: Warehouse Crew | B8: Rico Domingo | C8: My Tasks | D8: Even-numbered jobs: SJ-2026-00088, 00082, 00130, 00070, 00120, 00060, 00050, 00110
A9: Manager | B9: Grace Tan | C9: Dashboard | D9: Everything except Users & Roles
A10: Admin | B10: Mark Villar | C10: Dashboard | D10: Everything
A11: Finance | B11: Paolo Reyes | C11: Dashboard | D11: Read-only view of jobs, charges and audit trail
A12: Customer (no account) | B12: Any customer contact | C12: Public tracking page | D12: Sees only shipment status
A14: Sample shipments
A15: Today is 28 Sep 2026. Dispatcher = the customer's dispatcher; Crew = the covering warehouse person.
A16: Job | B16: Customer | C16: Dispatcher / Crew | D16: Stage now | E16: What is special about it
A17: SJ-2026-00101 | B17: Sample Trading Co. | C17: Ana / Ben | D17: Billing Ready | E17: Balance owed: client sent ₱140,000, we spent ₱150,400 and our fee is ₱3,500, so bill client ₱13,900. Quote ₱174,500. Has a pre-built PDF.
A18: SJ-2026-00095 | B18: Golden Harvest | C18: Cathy / Ben | D18: Documentation | E18: Document problems: Bill of Lading pending review, Certificate of Origin rejected, Import Permit missing. High priority.
A19: SJ-2026-00088 | B19: Pacific Rim | C19: Ana / Rico | D19: Sailed | E19: Clean, mid-journey job. Good for status updates.
A20: SJ-2026-00082 | B20: BlueWave | C20: Cathy / Rico | D20: Arrived at Port | E20: Overdue task (Lodge customs entry, due 24 Sep) and free storage expired 26 Sep.
A21: SJ-2026-00077 | B21: Meridian | C21: Ana / Ben | D21: Out for Delivery | E21: Delivery waiting to be confirmed. Free detention until 3 Oct.
A22: SJ-2026-00130 | B22: Sample Trading Co. | C22: Ana / Rico | D22: Customs Clearance | E22: Customs inspection (Red lane, Under Inspection). Urgent.
A23: SJ-2026-00070 | B23: Sample Trading Co. | C23: Ana / Rico | D23: Delivered | E23: Unquoted extra charge (Extra storage fee ₱6,800) and a payment with no receipt (Port handling fee ₱2,400). Empty container return is due, with detention ending in 2 days.
A24: SJ-2026-00065 | B24: Golden Harvest | C24: Cathy / Ben | D24: Exception Hold | E24: Open exception (HS code mismatch) waiting for approval. Customs payment is waiting on the client. Free storage ends tomorrow.
A25: SJ-2026-00120 | B25: Golden Harvest | C25: Cathy / Rico | D25: Customs Clearance | E25: Short on funds: duty ₱18,400 due 30 Sep, only ₱10,000 on hand, so short by ₱8,400. Free storage ends in 2 days.
A26: SJ-2026-00060 | B26: Pacific Rim | C26: Ana / Rico | D26: Billing Ready | E26: Refund due: fully funded, refund due to client ₱16,100. Has ₱5,000 markup on freight.
A27: SJ-2026-00050 | B27: BlueWave | C27: Cathy / Rico | D27: Closed | E27: Fully settled: money in exactly covers everything.
A28: SJ-2026-00110 | B28: Meridian | C28: Ana / Rico | D28: Booked | E28: All five documents missing. Brand-new job.
A30: Sample inquiries and quotations
A31: Item | B31: Value
A32: How to open | B32: Open apps/mockup/index.html in a browser (double-click the file). No server, no install.
A33: Browsers | B33: Chrome or Edge (latest) is the primary target. Spot-check Firefox and Safari.
A34: Screen sizes | B34: Desktop 1440 px wide for most cases. Section 12 covers tablet (768 px) and phone (400 px).
A35: "Today" | B35: The mockup's clock is fixed at Monday 28 September 2026. All overdue, due-in-N-days and storage-clock statements assume this date. Do not use your computer's date.
A36: Baseline | B36: The expected results in this plan were checked against the current build with an automated walkthrough of the same steps (more than 300 checks, all passing). If a screen differs from this plan, treat it as a finding.
A37: Data reset | B37: Data lives only in the open page. Refresh the page (F5) to restore the original sample data, then sign in again. Nothing is ever saved.
A38: Data between cases | B38: Cases within a section are designed to run in order on one page load. Where a case needs fresh data it says Refresh first.
A39: Mock content | B39: Every name, ID, amount and file is fictional. Buttons such as Open, View on a file, and Download PDF (except job SJ-2026-00101's PDF) do not open real files; they show a message saying so.
A41: Key numbers on a fresh page
A42: Audit Trail on a fresh page: All time 66 events, Today 1, Last 7 days 18, Last 30 days 64, This month 62.
A43: Card | B43: Manager, Admin, Finance | C43: Dispatcher Ana Cruz
A44: Active jobs | B44: 11 | C44: 7
...

Sheet Permission Matrix
A1: What each role may do
A3: Area | B3: Dispatcher | C3: Warehouse Crew | D3: Manager | E3: Admin | F3: Finance
A4: Dashboard | B4: Own customers' jobs only | C4: No | D4: All jobs | E4: All jobs | F4: All jobs
A5: Customers | B5: Full | C5: No | D5: Full | E5: Full | F5: No
A6: Inquiries and Quotations | B6: Full | C6: No | D6: Full | E6: Full | F6: No
A7: Shipment Jobs (list and detail) | B7: All jobs | C7: Assigned jobs only | D7: All | E7: All | F7: All, read-only
A8: Tasks | B8: Complete, reassign | C8: Own tasks only, complete (no reassign) | D8: Complete, reassign | E8: Complete, reassign | F8: No tab
A9: Documents | B9: Upload, approve, reject | C9: Upload only | D9: Upload, approve, reject | E9: Upload, approve, reject | F9: No tab
A10: Exceptions | B10: Raise | C10: Raise | D10: Raise, approve or reject | E10: Raise, approve or reject | F10: No tab
A11: Delivery and POD | B11: No tab | C11: Confirm delivery | D11: Confirm delivery | E11: Confirm delivery | F11: No tab
A12: Advance a job's stage or customs sub-stage | B12: Yes | C12: Yes (assigned jobs) | D12: Yes | E12: Yes | F12: No
A13: Customs lane, hold, clear hold | B13: No | C13: No | D13: Yes | E13: Yes | F13: No
A14: Status override (out of sequence) | B14: No | C14: No | D14: Yes | E14: Yes | F14: No
... A18: Audit Trail | B18: No | C18: No | D18: Yes | E18: Yes | F18: Yes

Sheet Coverage
A1: Feature coverage: where each feature is tested
A3: Feature | B3: Test cases
A4: Sign-in, account chooser, sign-out | B4: ACC-01, 04, 05, ADM-03 to 07
A5: Menus and page access by role | B5: ACC-02, 03, 11, DSP-32, WHC-02 to 04, 16, 17, MGR-34, FIN-01 to 04
A6: Global search | B6: ACC-06 to 08, FIN-05
A7: Notifications | B7: ACC-09
A8: Demo role switch | B8: ACC-10, 11
A9: Dashboard (all cards and panels) | B9: DSP-02 to 04, MGR-01 to 04, FIN-06, DAT-03
A10: My Tasks | B10: DSP-01, 04, WHC-01, 18
A11: Customers (list, search, detail, create, duplicate) | B11: DSP-05 to 10
A12: Inquiries | B12: DSP-11 to 13, 20
A13: Quotations, versions, approval, conversion | B13: DSP-14 to 19
A14: Job list (search, filter, density, flags) | B14: DSP-21, 22
... A33: Layout, keyboard, motion, labelling | B33: XC-01 to 05, WHC-19, CUS-13

Sheet Known Limitations
A1: Known limitations and open questions
A2: Not failures. Do not log these as defects unless behaviour differs from what is written here.
A4: # | B4: Note | C4: Decision owner | D4: Decision / comment
A5: KL-01 | B5: Nothing is saved. Refreshing restores the sample data.
A6: KL-02 | B6: The pre-built PDF for SJ-2026-00101 was not regenerated. It shows margin as quote minus all charges (₱20,600.00, 11.8%), while the screens now use "service fees plus markup" (₱3,500.00, 2.3%). Its file name also contains the word "invoice". The PDF's charges and quote match the screens. Decision needed: regenerate it.
A7: KL-03 | B7: Task status (Pending, Due, Overdue) is set when the job is created. Reassign changes the owner and date but does not recalculate the status. Moving a job forward does not complete its tasks.
A8: KL-04 | B8: A delivery reported with damage has no "resolved" step in the mockup, so billing stays blocked (see MGR-18). Decision needed on the damage-claim process.
A9: KL-05 | B9: View, Open and download buttons on documents, proof of delivery and deposits do not open real files. Uploads keep only the file name.
A10: KL-06 | B10: Overdue escalation emails are an illustration; nothing is sent.
A11: KL-07 | B11: There is no edit or delete for customers, inquiries, charges or deposits. A new customer gets placeholder city and contact email.
A12: KL-08 | B12: The account picker offers one person per role. The second person is reached by deactivating the first (section 2.2). The demo role switch ignores deactivation.
A13: KL-09 | B13: A Dispatcher can open every job in the Shipment Jobs list; "own jobs only" applies to the Dashboard. Decision needed: should the list be limited too?
A14: KL-10 | B14: Any role that can see a job can advance its status or customs stage (except Finance). The permission rules do not say who may. Decision needed.
A15: KL-11 | B15: For jobs without a quotation record, the quoted amount is estimated from the declared value divided by 6 and labelled illustrative.
A16: KL-12 | B16: The customer tracking page finds shipments by a guessable number. A real system would use a signed, expiring link or require two identifiers.
... A20: KL-16 | B20: The "Charges" column on the Dashboard's Billing readiness table is recorded charges (without markup); a job's "Total billed to client" includes markup. Both are correct for their labels.
